# exception

| 关键字 | 特点                                              |
| ------ | ------------------------------------------------- |
| try    | 里面的内容表示要使用的代码块，后面可以接多个catch |
| catch  | 捕获异常，并给程序员提示                          |
| throw  | 抛出异常                                          |

1. 包含头文件 exception.h
2. 可以自己实现一个异常类，该类继承自exception
3. 定义what()， 返回一个字符串
4. 类型匹配原理图：
   ![https://images2015.cnblogs.com/blog/610439/201601/610439-20160117105031678-298323359.png](https://images2015.cnblogs.com/blog/610439/201601/610439-20160117105031678-298323359.png)
5. c++标准异常类
   | 标准异常类       | 描述                                                   | 头文件    |
   | ---------------- | ------------------------------------------------------ | --------- |
   | exception        | 最通用的异常类，只报告异常的发生而不提供任何额外的信息 | exception |
   | runtime_error    | 只有在运行时才能检测出的错误                           | stdexcept |
   | rang_error       | 运行时错误：产生了超出有意义值域范围的结果             | stdexcept |
   | overflow_error   | 运行时错误：计算上溢                                   | stdexcept |
   | underflow_error  | 运行时错误：计算下溢                                   | stdexcept |
   | logic_error      | 程序逻辑错误                                           | stdexcept |
   | domain_error     | 逻辑错误：参数对应的结果值不存在                       | stdexcept |
   | invalid_argument | 逻辑错误：无效参数                                     | stdexcept |
   | length_error     | 逻辑错误：试图创建一个超出该类型最大长度的对象         | stdexcept |
   | out_of_range     | 逻辑错误：使用一个超出有效范围的值                     | stdexcept |
   | bad_alloc        | 内存动态分配错误                                       | new       |
   | bad_cast         | dynamic_cast类型转换出错                               | type_info |

## 方式一 继承抛出异常

```cpp
#include <exception>
#include <iostream>

class ZqhErr : public std::exception {
private:
    const char* m_str;

public:
    ZqhErr() = default;
    ZqhErr(char* str)
        : m_str(str)
    {
    }

    const char* what()
    {
        return "你错了，隔这搞笑了吧";
    }
};

```

```cpp
int Func(int a, int b)
{
    if (b == 0) {
        throw ZqhErr();
    }
    return a / b;
}

int main()
{
    cout << "请输入x， y的值" << endl;

    int x, y;
    cin >> x
        >> y;

    try {
        int c = Func(x, y);
        cout << "c的值是:" << c << endl;
    } catch (ZqhErr& e) {     //这里捕获抛出的异常
        std::cerr << e.what() << '\n';
        return -1;
    }

    return 0;
}

```

## 方式二 针对特定的参数抛出异常

```cpp
int Func(int a, int b)
{
    if (b == 0) {
        throw b; // throw抛出异常
    }
    return a / b;
}

int main()
{
    cout << "请输入x， y的值" << endl;

    int x, y;
    cin >> x
        >> y;

    try {
        int c = Func(x, y);
        cout << "c的值是:" << c << endl;
    } catch (int y) { // catch去捕获异常
        cout << "b的值有问题" << endl;
        return -1;
    }

    return 0;
}

```
